<xacro:macro name="parallel_gripper" params="parent">

  <!-- Base -->
  <link name="gripper_base"/>

  <joint name="gripper_mount_joint" type="fixed">
    <parent link="${parent}"/>
    <child link="gripper_base"/>
    <origin xyz="0 0 0.05"/>
  </joint>

  <!-- Left finger -->
  <link name="left_finger"/>
  <joint name="left_finger_joint" type="prismatic">
    <parent link="gripper_base"/>
    <child link="left_finger"/>
    <axis xyz="-1 0 0"/>
    <limit lower="0.0" upper="0.02" effort="10" velocity="0.1"/>
  </joint>

  <!-- Right finger -->
  <link name="right_finger"/>
  <joint name="right_finger_joint" type="prismatic">
    <parent link="gripper_base"/>
    <child link="right_finger"/>
    <axis xyz="1 0 0"/>
    <limit lower="0.0" upper="0.02" effort="10" velocity="0.1"/>
  </joint>

</xacro:macro>
